2024-02-03 10:51:05.606 | INFO     | routers.user:login:92 - login£º1²»´æÔÚ
2024-02-03 10:51:06.491 | INFO     | routers.user:login:92 - login£º1²»´æÔÚ
2024-02-03 10:51:06.941 | INFO     | routers.user:login:92 - login£º1²»´æÔÚ
2024-02-03 10:51:07.085 | INFO     | routers.user:login:92 - login£º1²»´æÔÚ
2024-02-03 10:51:07.241 | INFO     | routers.user:login:92 - login£º1²»´æÔÚ
2024-02-03 10:51:07.400 | INFO     | routers.user:login:92 - login£º1²»´æÔÚ
2024-02-03 10:51:13.077 | INFO     | routers.user:login:92 - login£º1²»´æÔÚ
2024-02-03 11:19:24.794 | INFO     | routers.user:login:92 - login£º1²»´æÔÚ
2024-02-03 12:23:45.270 | INFO     | routers.user:login:92 - login£º1²»´æÔÚ
2024-02-03 12:24:10.298 | INFO     | routers.user:login:92 - login£º1²»´æÔÚ
2024-02-03 12:26:53.652 | INFO     | routers.user:login:92 - login£º1²»´æÔÚ
2024-02-03 12:27:40.706 | INFO     | routers.user:login:92 - login£º1²»´æÔÚ
2024-02-03 12:27:58.664 | INFO     | routers.user:login:92 - login£º1²»´æÔÚ
2024-02-03 19:05:36.589 | ERROR    | routers.user:get_cure_user:84 - Traceback (most recent call last):
  File "E:\ÍøÕ¾\web\web\fastapi-backend\pythonProject\.venv\lib\site-packages\jose\jws.py", line 176, in _load
    signing_input, crypto_segment = jwt.rsplit(b".", 1)
ValueError: not enough values to unpack (expected 2, got 1)

During handling of the above exception, another exception occurred:

Traceback (most recent call last):
  File "E:\ÍøÕ¾\web\web\fastapi-backend\pythonProject\.venv\lib\site-packages\jose\jwt.py", line 142, in decode
    payload = jws.verify(token, key, algorithms, verify=verify_signature)
  File "E:\ÍøÕ¾\web\web\fastapi-backend\pythonProject\.venv\lib\site-packages\jose\jws.py", line 70, in verify
    header, payload, signing_input, signature = _load(token)
  File "E:\ÍøÕ¾\web\web\fastapi-backend\pythonProject\.venv\lib\site-packages\jose\jws.py", line 180, in _load
    raise JWSError("Not enough segments")
jose.exceptions.JWSError: Not enough segments

During handling of the above exception, another exception occurred:

Traceback (most recent call last):
  File "E:\ÍøÕ¾\web\web\fastapi-backend\pythonProject\routers\user.py", line 73, in get_cure_user
    payload = jwt.decode(token, SECRET_KEY, algorithms=[ALGORITHM])
  File "E:\ÍøÕ¾\web\web\fastapi-backend\pythonProject\.venv\lib\site-packages\jose\jwt.py", line 144, in decode
    raise JWTError(e)
jose.exceptions.JWTError: Not enough segments

2024-02-03 19:05:50.948 | ERROR    | routers.user:get_cure_user:84 - Traceback (most recent call last):
  File "E:\ÍøÕ¾\web\web\fastapi-backend\pythonProject\.venv\lib\site-packages\jose\jws.py", line 176, in _load
    signing_input, crypto_segment = jwt.rsplit(b".", 1)
ValueError: not enough values to unpack (expected 2, got 1)

During handling of the above exception, another exception occurred:

Traceback (most recent call last):
  File "E:\ÍøÕ¾\web\web\fastapi-backend\pythonProject\.venv\lib\site-packages\jose\jwt.py", line 142, in decode
    payload = jws.verify(token, key, algorithms, verify=verify_signature)
  File "E:\ÍøÕ¾\web\web\fastapi-backend\pythonProject\.venv\lib\site-packages\jose\jws.py", line 70, in verify
    header, payload, signing_input, signature = _load(token)
  File "E:\ÍøÕ¾\web\web\fastapi-backend\pythonProject\.venv\lib\site-packages\jose\jws.py", line 180, in _load
    raise JWSError("Not enough segments")
jose.exceptions.JWSError: Not enough segments

During handling of the above exception, another exception occurred:

Traceback (most recent call last):
  File "E:\ÍøÕ¾\web\web\fastapi-backend\pythonProject\routers\user.py", line 73, in get_cure_user
    payload = jwt.decode(token, SECRET_KEY, algorithms=[ALGORITHM])
  File "E:\ÍøÕ¾\web\web\fastapi-backend\pythonProject\.venv\lib\site-packages\jose\jwt.py", line 144, in decode
    raise JWTError(e)
jose.exceptions.JWTError: Not enough segments

2024-02-03 19:07:23.609 | ERROR    | routers.user:get_cure_user:84 - Traceback (most recent call last):
  File "E:\ÍøÕ¾\web\web\fastapi-backend\pythonProject\.venv\lib\site-packages\jose\jws.py", line 176, in _load
    signing_input, crypto_segment = jwt.rsplit(b".", 1)
ValueError: not enough values to unpack (expected 2, got 1)

During handling of the above exception, another exception occurred:

Traceback (most recent call last):
  File "E:\ÍøÕ¾\web\web\fastapi-backend\pythonProject\.venv\lib\site-packages\jose\jwt.py", line 142, in decode
    payload = jws.verify(token, key, algorithms, verify=verify_signature)
  File "E:\ÍøÕ¾\web\web\fastapi-backend\pythonProject\.venv\lib\site-packages\jose\jws.py", line 70, in verify
    header, payload, signing_input, signature = _load(token)
  File "E:\ÍøÕ¾\web\web\fastapi-backend\pythonProject\.venv\lib\site-packages\jose\jws.py", line 180, in _load
    raise JWSError("Not enough segments")
jose.exceptions.JWSError: Not enough segments

During handling of the above exception, another exception occurred:

Traceback (most recent call last):
  File "E:\ÍøÕ¾\web\web\fastapi-backend\pythonProject\routers\user.py", line 73, in get_cure_user
    payload = jwt.decode(token, SECRET_KEY, algorithms=[ALGORITHM])
  File "E:\ÍøÕ¾\web\web\fastapi-backend\pythonProject\.venv\lib\site-packages\jose\jwt.py", line 144, in decode
    raise JWTError(e)
jose.exceptions.JWTError: Not enough segments

2024-02-03 19:08:05.741 | ERROR    | routers.user:get_cure_user:84 - Traceback (most recent call last):
  File "E:\ÍøÕ¾\web\web\fastapi-backend\pythonProject\.venv\lib\site-packages\jose\jws.py", line 176, in _load
    signing_input, crypto_segment = jwt.rsplit(b".", 1)
ValueError: not enough values to unpack (expected 2, got 1)

During handling of the above exception, another exception occurred:

Traceback (most recent call last):
  File "E:\ÍøÕ¾\web\web\fastapi-backend\pythonProject\.venv\lib\site-packages\jose\jwt.py", line 142, in decode
    payload = jws.verify(token, key, algorithms, verify=verify_signature)
  File "E:\ÍøÕ¾\web\web\fastapi-backend\pythonProject\.venv\lib\site-packages\jose\jws.py", line 70, in verify
    header, payload, signing_input, signature = _load(token)
  File "E:\ÍøÕ¾\web\web\fastapi-backend\pythonProject\.venv\lib\site-packages\jose\jws.py", line 180, in _load
    raise JWSError("Not enough segments")
jose.exceptions.JWSError: Not enough segments

During handling of the above exception, another exception occurred:

Traceback (most recent call last):
  File "E:\ÍøÕ¾\web\web\fastapi-backend\pythonProject\routers\user.py", line 73, in get_cure_user
    payload = jwt.decode(token, SECRET_KEY, algorithms=[ALGORITHM])
  File "E:\ÍøÕ¾\web\web\fastapi-backend\pythonProject\.venv\lib\site-packages\jose\jwt.py", line 144, in decode
    raise JWTError(e)
jose.exceptions.JWTError: Not enough segments

